<?xml version='1.0'?>
<sdf version='1.7'>
  <model name='hand'>
    <link name='base_link'>
      <inertial>
        <pose>0.008822 0.016675 0.003853 0 -0 0</pose>
        <mass>0.14141</mass>
        <inertia>
          <ixx>0.000176591</ixx>
          <ixy>-2.34116e-05</ixy>
          <ixz>4.90335e-06</ixz>
          <iyy>8.16931e-05</iyy>
          <iyz>4.6094e-06</iyz>
          <izz>0.000250202</izz>
        </inertia>
      </inertial>
      <collision name='base_link_collision'>
        <pose>0 0 0 0 -0 0</pose>
        <geometry>
          <mesh>
            <scale>1 1 1</scale>
            <uri>model://hand/meshes/base_link.STL</uri>
          </mesh>
        </geometry>
      </collision>
      <collision name='base_link_fixed_joint_lump__Empty_Link1_collision_1'>
        <pose>0.039969 0.073739 0.004442 -1.5693 0 3.14159</pose>
        <geometry>
          <mesh>
            <scale>1 1 1</scale>
            <uri>model://hand/meshes/Empty_Link1.STL</uri>
          </mesh>
        </geometry>
      </collision>
      <collision name='base_link_fixed_joint_lump__Empty_Link3_collision_2'>
        <pose>-0.016731 0.073739 0.004491 -1.5708 -0 3.14159</pose>
        <geometry>
          <mesh>
            <scale>1 1 1</scale>
            <uri>model://hand/meshes/Empty_Link3.STL</uri>
          </mesh>
        </geometry>
      </collision>
      <collision name='base_link_fixed_joint_lump__Empty_Link4_collision_3'>
        <pose>-0.016554 -0.034133 0.005741 1.5708 -0 -3.0932</pose>
        <geometry>
          <mesh>
            <scale>1 1 1</scale>
            <uri>model://hand/meshes/Empty_Link4.STL</uri>
          </mesh>
        </geometry>
      </collision>
      <visual name='base_link_visual'>
        <pose>0 0 0 0 -0 0</pose>
        <geometry>
          <mesh>
            <scale>1 1 1</scale>
            <uri>model://hand/meshes/base_link.STL</uri>
          </mesh>
        </geometry>
      </visual>
      <visual name='base_link_fixed_joint_lump__Empty_Link1_visual_1'>
        <pose>0.039969 0.073739 0.004442 -1.5693 0 3.14159</pose>
        <geometry>
          <mesh>
            <scale>1 1 1</scale>
            <uri>model://hand/meshes/Empty_Link1.STL</uri>
          </mesh>
        </geometry>
      </visual>
      <visual name='base_link_fixed_joint_lump__Empty_Link3_visual_2'>
        <pose>-0.016731 0.073739 0.004491 -1.5708 -0 3.14159</pose>
        <geometry>
          <mesh>
            <scale>1 1 1</scale>
            <uri>model://hand/meshes/Empty_Link3.STL</uri>
          </mesh>
        </geometry>
      </visual>
      <visual name='base_link_fixed_joint_lump__Empty_Link4_visual_3'>
        <pose>-0.016554 -0.034133 0.005741 1.5708 -0 -3.0932</pose>
        <geometry>
          <mesh>
            <scale>1 1 1</scale>
            <uri>model://hand/meshes/Empty_Link4.STL</uri>
          </mesh>
        </geometry>
      </visual>
    </link>
    <joint name='10' type='revolute'>
      <pose relative_to='base_link'>0.031869 0.073739 0.004442 -1.56929 -0 -3.14159</pose>
      <parent>base_link</parent>
      <child>Empty_Link10</child>
      <axis>
        <xyz>1 0 0</xyz>
        <limit>
          <lower>-1e+16</lower>
          <upper>1e+16</upper>
        </limit>
        <dynamics>
          <spring_reference>0</spring_reference>
          <spring_stiffness>0</spring_stiffness>
        </dynamics>
      </axis>
    </joint>
    <link name='Empty_Link10'>
      <pose relative_to='10'>0 0 0 0 -0 0</pose>
      <inertial>
        <pose>-0.007546 5e-05 -0.022553 0 -0 0</pose>
        <mass>0.00892874</mass>
        <inertia>
          <ixx>8.97548e-07</ixx>
          <ixy>-3.3516e-09</ixy>
          <ixz>-2.29062e-08</ixz>
          <iyy>9.34091e-07</iyy>
          <iyz>7.84289e-09</iyz>
          <izz>3.39235e-07</izz>
        </inertia>
      </inertial>
      <collision name='Empty_Link10_collision'>
        <pose>0 0 0 0 -0 0</pose>
        <geometry>
          <mesh>
            <scale>1 1 1</scale>
            <uri>model://hand/meshes/Empty_Link10.STL</uri>
          </mesh>
        </geometry>
      </collision>
      <visual name='Empty_Link10_visual'>
        <pose>0 0 0 0 -0 0</pose>
        <geometry>
          <mesh>
            <scale>1 1 1</scale>
            <uri>model://hand/meshes/Empty_Link10.STL</uri>
          </mesh>
        </geometry>
      </visual>
    </link>
    <joint name='2' type='revolute'>
      <pose relative_to='base_link'>0.004269 0.073739 0.004491 -1.5708 -0 3.14159</pose>
      <parent>base_link</parent>
      <child>Empty_Link2</child>
      <axis>
        <xyz>1 0 0</xyz>
        <limit>
          <lower>-1e+16</lower>
          <upper>1e+16</upper>
        </limit>
        <dynamics>
          <spring_reference>0</spring_reference>
          <spring_stiffness>0</spring_stiffness>
        </dynamics>
      </axis>
    </joint>
    <link name='Empty_Link2'>
      <pose relative_to='2'>0 0 0 0 -0 0</pose>
      <inertial>
        <pose>-0.007577 0.00028 0.002494 0 -0 0</pose>
        <mass>0.0120824</mass>
        <inertia>
          <ixx>1.599e-06</ixx>
          <ixy>-3.12952e-09</ixy>
          <ixz>-3.27107e-08</ixz>
          <iyy>1.61011e-06</iyy>
          <iyz>5.02556e-08</iyz>
          <izz>4.46817e-07</izz>
        </inertia>
      </inertial>
      <collision name='Empty_Link2_collision'>
        <pose>0 0 0 0 -0 0</pose>
        <geometry>
          <mesh>
            <scale>1 1 1</scale>
            <uri>model://hand/meshes/Empty_Link2.STL</uri>
          </mesh>
        </geometry>
      </collision>
      <visual name='Empty_Link2_visual'>
        <pose>0 0 0 0 -0 0</pose>
        <geometry>
          <mesh>
            <scale>1 1 1</scale>
            <uri>model://hand/meshes/Empty_Link2.STL</uri>
          </mesh>
        </geometry>
      </visual>
    </link>
    <joint name='5' type='revolute'>
      <pose relative_to='base_link'>-0.017049 -0.02392 0.018241 -1.5708 -0 -1.5224</pose>
      <parent>base_link</parent>
      <child>Empty_Link5</child>
      <axis>
        <xyz>1 0 0</xyz>
        <limit>
          <lower>-1e+16</lower>
          <upper>1e+16</upper>
        </limit>
        <dynamics>
          <spring_reference>0</spring_reference>
          <spring_stiffness>0</spring_stiffness>
        </dynamics>
      </axis>
    </joint>
    <link name='Empty_Link5'>
      <pose relative_to='5'>0 0 0 0 -0 0</pose>
      <inertial>
        <pose>0.011248 0.00028 -0.030006 0 -0 0</pose>
        <mass>0.0120824</mass>
        <inertia>
          <ixx>1.599e-06</ixx>
          <ixy>-3.12952e-09</ixy>
          <ixz>-3.27108e-08</ixz>
          <iyy>1.61011e-06</iyy>
          <iyz>5.02556e-08</iyz>
          <izz>4.46817e-07</izz>
        </inertia>
      </inertial>
      <collision name='Empty_Link5_collision'>
        <pose>0 0 0 0 -0 0</pose>
        <geometry>
          <mesh>
            <scale>1 1 1</scale>
            <uri>model://hand/meshes/Empty_Link5.STL</uri>
          </mesh>
        </geometry>
      </collision>
      <visual name='Empty_Link5_visual'>
        <pose>0 0 0 0 -0 0</pose>
        <geometry>
          <mesh>
            <scale>1 1 1</scale>
            <uri>model://hand/meshes/Empty_Link5.STL</uri>
          </mesh>
        </geometry>
      </visual>
    </link>
    <joint name='6' type='revolute'>
      <pose relative_to='base_link'>-0.017049 -0.02392 0.018241 -1.5708 -0 -1.5224</pose>
      <parent>base_link</parent>
      <child>Empty_Link6</child>
      <axis>
        <xyz>1 0 0</xyz>
        <limit>
          <lower>-1e+16</lower>
          <upper>1e+16</upper>
        </limit>
        <dynamics>
          <spring_reference>0</spring_reference>
          <spring_stiffness>0</spring_stiffness>
        </dynamics>
      </axis>
    </joint>
    <link name='Empty_Link6'>
      <pose relative_to='6'>0 0 0 0 -0 0</pose>
      <inertial>
        <pose>0.011248 0.00028 -0.030006 0 -0 0</pose>
        <mass>0.0120824</mass>
        <inertia>
          <ixx>1.599e-06</ixx>
          <ixy>-3.12952e-09</ixy>
          <ixz>-3.27108e-08</ixz>
          <iyy>1.61011e-06</iyy>
          <iyz>5.02556e-08</iyz>
          <izz>4.46817e-07</izz>
        </inertia>
      </inertial>
      <collision name='Empty_Link6_collision'>
        <pose>0 0 0 0 -0 0</pose>
        <geometry>
          <mesh>
            <scale>1 1 1</scale>
            <uri>model://hand/meshes/Empty_Link6.STL</uri>
          </mesh>
        </geometry>
      </collision>
      <visual name='Empty_Link6_visual'>
        <pose>0 0 0 0 -0 0</pose>
        <geometry>
          <mesh>
            <scale>1 1 1</scale>
            <uri>model://hand/meshes/Empty_Link6.STL</uri>
          </mesh>
        </geometry>
      </visual>
    </link>
    <joint name='7' type='revolute'>
      <pose relative_to='base_link'>-0.049469 -0.026356 0.018241 -1.5708 -0 -1.5224</pose>
      <parent>base_link</parent>
      <child>Empty_Link7</child>
      <axis>
        <xyz>1 0 0</xyz>
        <limit>
          <lower>-1e+16</lower>
          <upper>1e+16</upper>
        </limit>
        <dynamics>
          <spring_reference>0</spring_reference>
          <spring_stiffness>0</spring_stiffness>
        </dynamics>
      </axis>
    </joint>
    <link name='Empty_Link7'>
      <pose relative_to='7'>0 0 0 0 -0 0</pose>
      <inertial>
        <pose>0.010415 5e-05 -0.022553 0 -0 0</pose>
        <mass>0.00892874</mass>
        <inertia>
          <ixx>8.97548e-07</ixx>
          <ixy>-3.35155e-09</ixy>
          <ixz>-2.29062e-08</ixz>
          <iyy>9.34091e-07</iyy>
          <iyz>7.84312e-09</iyz>
          <izz>3.39235e-07</izz>
        </inertia>
      </inertial>
      <collision name='Empty_Link7_collision'>
        <pose>0 0 0 0 -0 0</pose>
        <geometry>
          <mesh>
            <scale>1 1 1</scale>
            <uri>model://hand/meshes/Empty_Link7.STL</uri>
          </mesh>
        </geometry>
      </collision>
      <visual name='Empty_Link7_visual'>
        <pose>0 0 0 0 -0 0</pose>
        <geometry>
          <mesh>
            <scale>1 1 1</scale>
            <uri>model://hand/meshes/Empty_Link7.STL</uri>
          </mesh>
        </geometry>
      </visual>
    </link>
    <joint name='8' type='revolute'>
      <pose relative_to='base_link'>-0.009131 0.073739 0.004491 -1.5708 -0 3.14159</pose>
      <parent>base_link</parent>
      <child>Empty_Link8</child>
      <axis>
        <xyz>1 0 0</xyz>
        <limit>
          <lower>-1e+16</lower>
          <upper>1e+16</upper>
        </limit>
        <dynamics>
          <spring_reference>0</spring_reference>
          <spring_stiffness>0</spring_stiffness>
        </dynamics>
      </axis>
    </joint>
    <link name='Empty_Link8'>
      <pose relative_to='8'>0 0 0 0 -0 0</pose>
      <inertial>
        <pose>0.007654 5e-05 -0.022553 0 -0 0</pose>
        <mass>0.00892874</mass>
        <inertia>
          <ixx>8.97548e-07</ixx>
          <ixy>-3.35161e-09</ixy>
          <ixz>-2.29063e-08</ixz>
          <iyy>9.34091e-07</iyy>
          <iyz>7.84278e-09</iyz>
          <izz>3.39235e-07</izz>
        </inertia>
      </inertial>
      <collision name='Empty_Link8_collision'>
        <pose>0 0 0 0 -0 0</pose>
        <geometry>
          <mesh>
            <scale>1 1 1</scale>
            <uri>model://hand/meshes/Empty_Link8.STL</uri>
          </mesh>
        </geometry>
      </collision>
      <visual name='Empty_Link8_visual'>
        <pose>0 0 0 0 -0 0</pose>
        <geometry>
          <mesh>
            <scale>1 1 1</scale>
            <uri>model://hand/meshes/Empty_Link8.STL</uri>
          </mesh>
        </geometry>
      </visual>
    </link>
    <joint name='9' type='revolute'>
      <pose relative_to='base_link'>0.004269 0.073739 0.004491 -1.5708 -0 3.14159</pose>
      <parent>base_link</parent>
      <child>Empty_Link9</child>
      <axis>
        <xyz>1 0 0</xyz>
        <limit>
          <lower>-1e+16</lower>
          <upper>1e+16</upper>
        </limit>
        <dynamics>
          <spring_reference>0</spring_reference>
          <spring_stiffness>0</spring_stiffness>
        </dynamics>
      </axis>
    </joint>
    <link name='Empty_Link9'>
      <pose relative_to='9'>0 0 0 0 -0 0</pose>
      <inertial>
        <pose>-0.007546 5e-05 -0.022553 0 -0 0</pose>
        <mass>0.00892874</mass>
        <inertia>
          <ixx>8.97548e-07</ixx>
          <ixy>-3.3516e-09</ixy>
          <ixz>-2.29062e-08</ixz>
          <iyy>9.34091e-07</iyy>
          <iyz>7.8429e-09</iyz>
          <izz>3.39235e-07</izz>
        </inertia>
      </inertial>
      <collision name='Empty_Link9_collision'>
        <pose>0 0 0 0 -0 0</pose>
        <geometry>
          <mesh>
            <scale>1 1 1</scale>
            <uri>model://hand/meshes/Empty_Link9.STL</uri>
          </mesh>
        </geometry>
      </collision>
      <visual name='Empty_Link9_visual'>
        <pose>0 0 0 0 -0 0</pose>
        <geometry>
          <mesh>
            <scale>1 1 1</scale>
            <uri>model://hand/meshes/Empty_Link9.STL</uri>
          </mesh>
        </geometry>
      </visual>
    </link>
  </model>
</sdf>
